Workbook

Sheet DP və TP
A1: S/N | B1: Hüquqi aktın adı | C1: Bənd | D1: Tədbirin adı | E1: Alt tədbirin adı | F1: İcra müddəti | G1: Hüquqi akt üzrə icraçı | H1: Hüquqi akt üzrə Nazirliyin icraçı statusu | I1: Nazirlik üzrə icraçı | J1: Nazirlik üzrə Agentliyin icraçı statusu | K1: Hesabatlılığın təmin olunması üzrə | L1: Agentlik üzrə məsul bölmə | M1: İndikator | N1: Nəticə göstəricisi | O1: Maliyyə yükü | P1: 1-ci rüb plan | Q1: 1-ci rüb faktiki görülmüş iş (Monitorinq zamanı) | R1: 2-ci rüb plan | S1: 2-ci rüb faktiki görülmüş iş (Monitorinq zamanı) | T1: 3-cü rüb plan | U1: 3-cü rüb faktiki görülmüş iş (Monitorinq zamanı) | V1: 4-cü rüb plan | W1: 4-cü rüb faktiki görülmüş iş (Monitorinq zamanı) | X1: I rüb üzrə | Y1: II rüb üzrə | Z1: Yarımillik | AA1: III rüb üzrə | AB1: IV rüb üzrə | AC1: İllik | AD1: Əlavə edilmə rübü
A2: 1 | B2: “Respublikada ailə institutunun möhkəmləndirilməsi üzrə 2021–2025-ci illər üçün Milli Fəaliyyət Planı” | C2: 5.4.5. | D2: Hədəf qrupların hazırlanması və təqdim edilməsi | F2: mütəmadi | G2: Nümunə Sosial Xidmətlər Nazirliyi | H2: Əsas icraçı | I2: Nur Agentliyi, Hüquqi təminat şöbəsi, Aran Agentliyi | J2: Digər icraçı | K2: Hüquqi akt üzrə | L2: ÇAUNF,LAÜT | M2: İmzalanmış əməkdaşlıq sənədlərinin sayı | N2: 30 | P2: 7 | Q2: 6 | R2: 5 | S2: Elektron platformada 47 yeni məlumat təqdim edilmişdir | T2: 6 | V2: 7 | X2: Qismən icra | Y2: Tam icra | AA2: Qismən icra | AB2: Tam icra | AD2: 1
A3: 2 | B3: “Respublikada ailə institutunun möhkəmləndirilməsi üzrə 2021–2025-ci illər üçün Milli Fəaliyyət Planı” | C3: 6.3.9. | D3: Pilot layihə çərçivəsində icma əsaslı proqramların gücləndirilməsi | F3: mütəmadi | G3: Nümunə Sosial Xidmətlər Nazirliyi | H3: Əsas icraçı | I3: Aran Agentliyi, Nur Agentliyi | J3: Əsas icraçı | K3: Hüquqi akt üzrə | L3: ÇAUNF, LAÜT | M3: Qəbul edilmiş müraciətlərin sayı | N3: 25 | P3: 4 | Q3: 18 | R3: 7 | S3: Elektron platformada 60 yeni məlumat təqdim edilmişdir | T3: 7 | V3: 5 | X3: Qismən icra | Y3: Qismən icra | AA3: Qismən icra | AB3: Qismən icra | AD3: 1
A4: 3 | B4: “Respublikada ailə institutunun möhkəmləndirilməsi üzrə 2021–2025-ci illər üçün Milli Fəaliyyət Planı” | C4: 9.6.4. | D4: İcma əsaslı proqramların hazırlanması və təqdim edilməsi | F4: mütəmadi | G4: Nümunə Sosial Xidmətlər Nazirliyi | H4: Digər icraçı | I4: Aran Agentliyi, Zirvə Agentliyi, Koordinasiya şöbəsi | J4: Əsas icraçı | K4: Hüquqi akt üzrə | L4: BOV | M4: Hazırlanmış metodik vəsaitlərin sayı | N4: Hədəf qrupun tam əhatə olunması | O4: Vahidin dəyəri orta hesabla 755 azn | P4: Tədbirlərin təşkili | Q4: Hesabat dövründə 23 nəfər hədəf qrupdan tədbirlərə cəlb edilmişdir | R4: Siyahının formalaşdırılması | S4: 40 qurumla əməkdaşlıq çərçivəsində görüşlər təşkil olunmuşdur | T4: İcra mexanizminin tətbiqi | V4: Hədəf qrupun müəyyən edilməsi | X4: Tam icra | Y4: Tam icra | AA4: Tam icra | AB4: Tam icra | AD4: 1
A5: 4 | B5: “Respublikada ailə institutunun möhkəmləndirilməsi üzrə 2021–2025-ci illər üçün Milli Fəaliyyət Planı” | C5: 8.6.2. | D5: Ailələrin hazırlanması və təqdim edilməsi | F5: mütəmadi | G5: Nümunə Sosial Xidmətlər Nazirliyi | H5: Əsas icraçı | I5: Aran Agentliyi, Koordinasiya şöbəsi | J5: Əsas icraçı | K5: Hüquqi akt üzrə | L5: ÇAUNF, LAÜT, BOV | Q5: 48 iştirakçının əhatə olunduğu təlim sessiyaları keçirilmişdir | S5: Hesabat dövründə 52 nəfər hədəf qrupdan tədbirlərə cəlb edilmişdir | X5: Tam icra | Y5: Tam icra | AA5: Tam icra | AB5: Tam icra | AD5: 1
A6: 5 | B6: “Respublikada ailə institutunun möhkəmləndirilməsi üzrə 2021–2025-ci illər üçün Milli Fəaliyyət Planı” | C6: 8.6.6. | D6: Regionlar üzrə metodoloji vəsaitlərin hazırlanması və təqdim edilməsi | F6: mütəmadi | G6: Nümunə Sosial Xidmətlər Nazirliyi | H6: Əsas icraçı | I6: Koordinasiya şöbəsi, Aran Agentliyi | J6: Digər icraçı | K6: Hüquqi akt üzrə | L6: ÇAUNF, ÖŞŞÖG, LAÜT | M6: İmzalanmış əməkdaşlıq sənədlərinin sayı | N6: 81 | P6: 10 | Q6: Elektron platformada 51 yeni məlumat təqdim edilmişdir | R6: 14 | S6: İş planına uyğun olaraq müvafiq tədbirlər icra olunmuşdur | T6: 20 | V6: 9 | X6: Qismən icra | Y6: İcra olunmayıb | AA6: Qismən icra | AB6: İcra olunmayıb | AD6: 1
A7: 6 | B7: “Respublikada ailə institutunun möhkəmləndirilməsi üzrə 2021–2025-ci illər üçün Milli Fəaliyyət Planı” | C7: 5.5.25. | D7: Hədəf qrup üzrə yaşlı vətəndaşların əhatə dairəsinin artırılması | F7: mütəmadi | G7: Nümunə Sosial Xidmətlər Nazirliyi | H7: Əsas icraçı | I7: Aran Agentliyi, Koordinasiya şöbəsi | J7: Əsas icraçı | K7: Hüquqi akt üzrə | L7: ÇAUNF | Q7: 8 | X7: Tam icra | Y7: İcra müddətinə var | AA7: Tam icra | AB7: İcra müddətinə var | AD7: 1
A8: 7 | B8: “Respublikada ailə institutunun möhkəmləndirilməsi üzrə 2021–2025-ci illər üçün Milli Fəaliyyət Planı” | C8: 3.3.26. | D8: Əməkdaşlıq protokollarının təşkil edilməsi | F8: mütəmadi | G8: Nümunə Sosial Xidmətlər Nazirliyi | H8: Əsas icraçı | I8: İnkişaf siyasəti şöbəsi, Aran Agentliyi | J8: Əsas icraçı | K8: Hüquqi akt üzrə | L8: ZCÖSÇ | N8: 318 | P8: 74 | Q8: Planlaşdırılan işlər üzrə 23 fəaliyyət həyata keçirilmişdir | R8: 54 | S8: 34 iştirakçının əhatə olunduğu təlim sessiyaları keçirilmişdir | T8: 50 | V8: 60 | X8: Tam icra | Y8: Tam icra | AA8: Tam icra | AB8: Tam icra | AD8: 1
A9: 8 | B9: “Respublikada ailə institutunun möhkəmləndirilməsi üzrə 2021–2025-ci illər üçün Milli Fəaliyyət Planı” | C9: 2.2.15. | D9: Hədəf qrupların inkişaf etdirilməsi | F9: mütəmadi | G9: Nümunə Sosial Xidmətlər Nazirliyi | H9: Digər icraçı | I9: İnkişaf siyasəti şöbəsi, Aran Agentliyi | J9: Digər icraçı | K9: Hüquqi akt üzrə | L9: ZCÖSÇ | N9: 238 | P9: 40 | Q9: 9 qurumla əməkdaşlıq çərçivəsində görüşlər təşkil olunmuşdur | R9: 55 | S9: İş planına uyğun olaraq müvafiq tədbirlər icra olunmuşdur | T9: 28 | V9: 61 | X9: Tam icra | Y9: Qismən icra | AA9: Tam icra | AB9: Qismən icra | AD9: 1
A10: 9 | B10: “Respublikada ailə institutunun möhkəmləndirilməsi üzrə 2021–2025-ci illər üçün Milli Fəaliyyət Planı” | C10: 7.4.17. | D10: Pilot layihə çərçivəsində gənclərin davamlı olaraq həyata keçirilməsi | F10: mütəmadi | G10: Nümunə Sosial Xidmətlər Nazirliyi | H10: Əsas icraçı | I10: İnkişaf siyasəti şöbəsi, Aran Agentliyi | J10: Digər icraçı | K10: Hüquqi akt üzrə | L10: ZCÖSÇ | N10: 1 | P10: 1 | Q10: İş planına uyğun olaraq müvafiq tədbirlər icra olunmuşdur | R10: 1 | S10: 1 | T10: 1 | V10: 1 | X10: Qismən icra | Y10: İcra olunmayıb, prioritet deyil | AA10: Qismən icra | AB10: İcra olunmayıb, prioritet deyil | AD10: 1
A11: 10 | B11: “Respublikada ailə institutunun möhkəmləndirilməsi üzrə 2021–2025-ci illər üçün Milli Fəaliyyət Planı” | C11: 7.8.18. | D11: Hədəf qrup üzrə hədəf qrupların inkişaf etdirilməsi | F11: mütəmadi | G11: Nümunə Sosial Xidmətlər Nazirliyi | H11: Digər icraçı | I11: İnkişaf siyasəti şöbəsi, Aran Agentliyi | J11: Digər icraçı | K11: Tapşırıqların İcrasına Nəzarət platforması üzrə | L11: ZCÖSÇ | N11: 1245 | P11: 151 | Q11: Hesabat dövründə 30 nəfər hədəf qrupdan tədbirlərə cəlb edilmişdir | R11: 415 | S11: Hesabat dövründə 4 nəfər hədəf qrupdan tədbirlərə cəlb edilmişdir | T11: 180 | V11: 413 | X11: Tam icra | Y11: Tam icra | AA11: Tam icra | AB11: Tam icra | AD11: 1
A12: 11 | B12: “Respublikada ailə institutunun möhkəmləndirilməsi üzrə 2021–2025-ci illər üçün Milli Fəaliyyət Planı” | C12: 2.8.15. | D12: Təlim modullarının gücləndirilməsi | F12: mütəmadi | G12: Nümunə Sosial Xidmətlər Nazirliyi | H12: Əsas icraçı | I12: İnkişaf siyasəti şöbəsi, Aran Agentliyi | J12: Digər icraçı | K12: Hüquqi akt üzrə | L12: ZCÖSÇ | N12: 7 | P12: 2 | Q12: Metodik təlimatın layihəsi hazırlanmış və razılaşdırılmışdır | R12: 1 | S12: Hesabat dövründə 11 nəfər hədəf qrupdan tədbirlərə cəlb edilmişdir | T12: 1 | V12: 2 | X12: Tam icra | Y12: Tam icra | AA12: Tam icra | AB12: Tam icra | AD12: 1
A13: 12 | B13: “Respublikada ailə institutunun möhkəmləndirilməsi üzrə 2021–2025-ci illər üçün Milli Fəaliyyət Planı” | C13: 5.4.20. | D13: Hədəf qrup üzrə statistik məlumat bazasının genişləndirilməsi | F13: mütəmadi | G13: Nümunə Sosial Xidmətlər Nazirliyi | H13: Əsas icraçı | I13: İnkişaf siyasəti şöbəsi, Aran Agentliyi | J13: Əsas icraçı | K13: Tapşırıqların İcrasına Nəzarət platforması üzrə | L13: ZCÖSÇ | Q13: Elektron platformada 27 yeni məlumat təqdim edilmişdir | X13: Tam icra | Y13: İcra müddətinə var | AA13: Tam icra | AB13: İcra müddətinə var | AD13: 1
A14: 13 | B14: “Respublikada ailə institutunun möhkəmləndirilməsi üzrə 2021–2025-ci illər üçün Milli Fəaliyyət Planı” | C14: 2.3.19. | D14: Pilot layihə çərçivəsində elektron platformanın genişləndirilməsi | F14: mütəmadi | G14: Nümunə Sosial Xidmətlər Nazirliyi | H14: Əsas icraçı | I14: İnkişaf siyasəti şöbəsi, Aran Agentliyi | J14: Digər icraçı | K14: Tapşırıqların İcrasına Nəzarət platforması üzrə | L14: ZCÖSÇ | N14: 474 | P14: 151 | Q14: Metodik təlimatın layihəsi hazırlanmış və razılaşdırılmışdır | R14: 124 | S14: Hesabat dövründə 56 nəfər hədəf qrupdan tədbirlərə cəlb edilmişdir | T14: 86 | V14: 107 | X14: Tam icra | Y14: Tam icra | AA14: Tam icra | AB14: Tam icra | AD14: 1
A15: 14 | B15: “Respublikada ailə institutunun möhkəmləndirilməsi üzrə 2021–2025-ci illər üçün Milli Fəaliyyət Planı” | C15: 6.6.19. | D15: Pilot layihə çərçivəsində təlim modullarının təkmilləşdirilməsi | F15: mütəmadi | G15: Nümunə Sosial Xidmətlər Nazirliyi | H15: Əsas icraçı | I15: İnkişaf siyasəti şöbəsi, Aran Agentliyi | J15: Digər icraçı | K15: Hüquqi akt üzrə | L15: ZCÖSÇ | Q15: Planlaşdırılan işlər üzrə 48 fəaliyyət həyata keçirilmişdir | X15: Tam icra | Y15: İcra müddətinə var | AA15: Tam icra | AB15: İcra müddətinə var | AD15: 1
A16: 15 | B16: “Respublikada ailə institutunun möhkəmləndirilməsi üzrə 2021–2025-ci illər üçün Milli Fəaliyyət Planı” | C16: 8.5.10. | D16: İcma əsaslı proqramların gücləndirilməsi | F16: mütəmadi | G16: Nümunə Sosial Xidmətlər Nazirliyi | H16: Əsas icraçı | I16: Aran Agentliyi, İnkişaf siyasəti şöbəsi | J16: Digər icraçı | K16: Hüquqi akt üzrə | L16: ZCÖSÇ | N16: 578 | P16: 55 | Q16: Hesabat dövründə 33 nəfər hədəf qrupdan tədbirlərə cəlb edilmişdir | R16: 100 | S16: Metodik təlimatın layihəsi hazırlanmış və razılaşdırılmışdır | T16: 87 | V16: 173 | X16: Tam icra | Y16: Qismən icra | AA16: Tam icra | AB16: Qismən icra | AD16: 1
A17: 16 | B17: “Respublikada ailə institutunun möhkəmləndirilməsi üzrə 2021–2025-ci illər üçün Milli Fəaliyyət Planı” | C17: 3.6.14. | D17: İllik plana uyğun qiymətləndirmə meyarlarının inkişaf etdirilməsi | F17: mütəmadi | G17: Nümunə Sosial Xidmətlər Nazirliyi | H17: Əsas icraçı | I17: Aran Agentliyi, İnkişaf siyasəti şöbəsi | J17: Əsas icraçı | K17: Hüquqi akt üzrə | L17: ZCÖSÇ | N17: 205 | P17: 45 | Q17: İş planına uyğun olaraq müvafiq tədbirlər icra olunmuşdur | R17: 55 | S17: Planlaşdırılan işlər üzrə 45 fəaliyyət həyata keçirilmişdir | T17: 89 | V17: 123 | X17: Tam icra | Y17: Tam icra | AA17: Tam icra | AB17: Tam icra | AD17: 1
A18: 17 | B18: “Respublikada ailə institutunun möhkəmləndirilməsi üzrə 2021–2025-ci illər üçün Milli Fəaliyyət Planı” | C18: 8.6.13. | D18: Metodoloji vəsaitlərin təkmilləşdirilməsi | F18: mütəmadi | G18: Nümunə Sosial Xidmətlər Nazirliyi | H18: Əsas icraçı | I18: Aran Agentliyi, İnkişaf siyasəti şöbəsi | J18: Əsas icraçı | K18: Hüquqi akt üzrə | L18: ZCÖSÇ | N18: 1287 | P18: 115 | Q18: 17 qurumla əməkdaşlıq çərçivəsində görüşlər təşkil olunmuşdur | R18: 179 | S18: Hesabat dövründə 45 nəfər hədəf qrupdan tədbirlərə cəlb edilmişdir | T18: 247 | V18: 376 | X18: İcra olunmayıb | Y18: Qismən icra | AA18: İcra olunmayıb | AB18: Qismən icra | AD18: 1
A19: 18 | B19: “Respublikada ailə institutunun möhkəmləndirilməsi üzrə 2021–2025-ci illər üçün Milli Fəaliyyət Planı” | C19: 9.6.27. | D19: Pilot layihə çərçivəsində könüllü qrupların əhatə dairəsinin artırılması | F19: mütəmadi | G19: Nümunə Sosial Xidmətlər Nazirliyi | H19: Əsas icraçı | I19: Aran Agentliyi, İnkişaf siyasəti şöbəsi | J19: Əsas icraçı | K19: Hüquqi akt üzrə | L19: ZCÖSÇ | Q19: Planlaşdırılan işlər üzrə 56 fəaliyyət həyata keçirilmişdir | S19: 23 iştirakçının əhatə olunduğu təlim sessiyaları keçirilmişdir | X19: İcra olunmayıb, prioritet deyil | Y19: Tam icra | AA19: İcra olunmayıb, prioritet deyil | AB19: Tam icra | AD19: 1
A20: 19 | B20: “Respublikada ailə institutunun möhkəmləndirilməsi üzrə 2021–2025-ci illər üçün Milli Fəaliyyət Planı” | C20: 2.8.8. | D20: Könüllü qrupların təhlilinin aparılması | F20: mütəmadi | G20: Nümunə Sosial Xidmətlər Nazirliyi | H20: Əsas icraçı | I20: Aran Agentliyi, İnkişaf siyasəti şöbəsi | J20: Əsas icraçı | K20: Hüquqi akt üzrə | L20: ZCÖSÇ | Q20: 46 iştirakçının əhatə olunduğu təlim sessiyaları keçirilmişdir | X20: İcra olunmayıb | Y20: İcra müddətinə var | AA20: İcra olunmayıb | AB20: İcra müddətinə var | AD20: 1
A21: 20 | B21: “Respublikada ailə institutunun möhkəmləndirilməsi üzrə 2021–2025-ci illər üçün Milli Fəaliyyət Planı” | C21: 8.8.14. | D21: Pilot layihə çərçivəsində ailələrin inkişaf etdirilməsi | F21: mütəmadi | G21: Nümunə Sosial Xidmətlər Nazirliyi | H21: Əsas icraçı | I21: Aran Agentliyi, İnkişaf siyasəti şöbəsi | J21: Əsas icraçı | K21: Hüquqi akt üzrə | L21: ZCÖSÇ | X21: İcra olunmayıb, prioritet deyil | Y21: İcra olunmayıb, prioritet deyil | AA21: İcra olunmayıb, prioritet deyil | AB21: İcra olunmayıb, prioritet deyil | AD21: 1
A22: 21 | B22: Respublikada uşaq hüquqlarının qorunması üzrə 2023–2028-ci illər üçün Dövlət Proqramı | C22: 1.8.12. | D22: Regionlar üzrə təlim modullarının davamlı olaraq həyata keçirilməsi | E22: Statistik məlumat bazasının genişləndirilməsi | F22: 2025–2030 | G22: Mehr Qurumu, Qaya Qurumu, Səma Nazirliyi, Bəhər Nazirliyi, Dəniz Nazirliyi, Nümunə Sosial Xidmətlər Nazirliyi, Lalə Qurumu, Çinar Komitəsi, Yaylaq Qapalı Səhmdar Cəmiyyəti, Alov Agentliyi, Qeyri- Hökumət Təşkilatlarına Dövlət Dəstəyi Agentliyi | H22: Digər icraçı | I22: DÜİ, XIŞBI, MKFÜD, NMZ | J22: Digər icraçı | K22: Hüquqi akt üzrə | L22: YYÇX, ÇAUNF, ÖŞŞÖG | Q22: Metodik təlimatın layihəsi hazırlanmış və razılaşdırılmışdır | X22: Qismən icra | Y22: İcra olunmayıb, prioritet deyil | AA22: Qismən icra | AB22: İcra olunmayıb, prioritet deyil | AD22: 1
A23: 22 | B23: Respublikada uşaq hüquqlarının qorunması üzrə 2023–2028-ci illər üçün Dövlət Proqramı | E23: Hədəf qrup üzrə regional mərkəzlərin təhlilinin aparılması | F23: 2025–2030 | G23: Mehr Qurumu, Qaya Qurumu, Səma Nazirliyi, Bəhər Nazirliyi, Dəniz Nazirliyi, Nümunə Sosial Xidmətlər Nazirliyi, Lalə Qurumu, Çinar Komitəsi, Yaylaq Qapalı Səhmdar Cəmiyyəti, Alov Agentliyi, Qeyri- Hökumət Təşkilatlarına Dövlət Dəstəyi Agentliyi | H23: Digər icraçı | I23: DÜİ, XIŞBI, MKFÜD, NMZ | J23: Digər icraçı | K23: Hüquqi akt üzrə | L23: YYÇX, ÇAUNF, ÖŞŞÖG | X23: İcra müddətinə var | Y23: İcra müddətinə var | AA23: İcra müddətinə var | AB23: İcra müddətinə var | AD23: 1
A24: 23 | B24: Respublikada uşaq hüquqlarının qorunması üzrə 2023–2028-ci illər üçün Dövlət Proqramı | E24: İllik plana uyğun sosial xidmətlərin inkişaf etdirilməsi | F24: 2025–2030 | G24: Mehr Qurumu, Qaya Qurumu, Səma Nazirliyi, Bəhər Nazirliyi, Dəniz Nazirliyi, Nümunə Sosial Xidmətlər Nazirliyi, Lalə Qurumu, Çinar Komitəsi, Yaylaq Qapalı Səhmdar Cəmiyyəti, Alov Agentliyi, Qeyri- Hökumət Təşkilatlarına Dövlət Dəstəyi Agentliyi | H24: Digər icraçı | I24: DÜİ, XIŞBI, MKFÜD, NMZ | J24: Digər icraçı | K24: Hüquqi akt üzrə | L24: YYÇX, ÇAUNF, ÖŞŞÖG | X24: İcra olunmayıb | Y24: İcra müddətinə var | AA24: İcra olunmayıb | AB24: İcra müddətinə var | AD24: 1
A25: 24 | B25: Respublikada gənclərin məşğulluğunun artırılması üzrə 2020–2024-ci illər üçün Strategiyanın həyata keçirilməsi üzrə Tədbirlər Planı | C25: 7.22.8 | D25: İllik plana uyğun ailələrin əhatə dairəsinin artırılması | E25: Pilot layihə çərçivəsində informasiya sisteminin təhlilinin aparılması | F25: 2021-2025 | G25: Nümunə Sosial Xidmətlər Nazirliyi | H25: Əsas icraçı | I25: Aran Agentliyi, Hüquqi təminat şöbəsi, Sahil Qurumu, Beynəlxalq tərəfdaşlıq şöbəsi | J25: Əsas icraçı | K25: Tapşırıqların İcrasına Nəzarət platforması üzrə | L25: ÇAUNF,LAÜT | M25: Qəbul edilmiş müraciətlərin sayı | N25: 100 | P25: 30 | Q25: 83 | R25: 18 | S25: Metodik təlimatın layihəsi hazırlanmış və razılaşdırılmışdır | T25: 34 | V25: 34 | X25: Tam icra | Y25: İcra olunmayıb | AA25: Tam icra | AB25: İcra olunmayıb | AD25: 1
A26: 25 | B26: “Respublikada yaşlı vətəndaşların sosial dəstəyi üzrə 2023–2025-ci illər üçün Konsepsiyanın icrası üzrə Fəaliyyət Planı” | C26: 7.1.7.5. | D26: Regionlar üzrə statistik məlumat bazasının davamlı olaraq həyata keçirilməsi | F26: mütəmadi | G26: Nümunə Sosial Xidmətlər Nazirliyi | H26: Əsas icraçı | I26: Aran Agentliyi, Rəqəmsal transformasiya şöbəsi, Meydan Agentliyi, Koordinasiya şöbəsi | J26: Əsas icraçı | K26: Tapşırıqların İcrasına Nəzarət platforması üzrə | L26: ÇAUNF | M26: Yenilənmiş məlumat bazalarının sayı | N26: Hədəf qrup üzrə 24 tədbirin keçirilməsi | P26: Siyahının formalaşdırılması | Q26: Elektron platformada 37 yeni məlumat təqdim edilmişdir | R26: Hesabatın hazırlanması | T26: İcra mexanizminin tətbiqi | V26: Hazırlıq işlərinin aparılması | X26: Tam icra | Y26: Tam icra | AA26: Tam icra | AB26: Tam icra | AD26: 1
A27: 26 | B27: “Respublikada yaşlı vətəndaşların sosial dəstəyi üzrə 2023–2025-ci illər üçün Konsepsiyanın icrası üzrə Fəaliyyət Planı” | C27: 8.2.5.6. | D27: Tədqiqat işlərinin əhatə dairəsinin artırılması | F27: mütəmadi | G27: Nümunə Sosial Xidmətlər Nazirliyi | H27: Digər icraçı | I27: Rəqəmsal transformasiya şöbəsi, Aran Agentliyi, Koordinasiya şöbəsi | J27: Digər icraçı | K27: Hüquqi akt üzrə | L27: ÇAUNF,LAÜT,YYÇX | M27: Keçirilmiş maarifləndirmə tədbirlərinin sayı | N27: Hədəf qrup üzrə 40 tədbirin keçirilməsi | P27: 1 | Q27: 4 | R27: 1 | S27: Metodik təlimatın layihəsi hazırlanmış və razılaşdırılmışdır | T27: 1 | V27: Hədəf qrupun müəyyən edilməsi | X27: İcra olunmayıb, prioritet deyil | Y27: Tam icra | AA27: İcra olunmayıb, prioritet deyil | AB27: Tam icra | AD27: 1
A28: 27 | B28: Respublikada ətraf mühitin mühafizəsi üzrə 2020–2025-ci illər üçün Tədbirlər Proqramı | C28: 4.5.3. | D28: Hədəf qrup üzrə statistik məlumat bazasının əhatə dairəsinin artırılması | F28: Mütəmadi | G28: Bəhər Nazirliyi, Orxan Nazirliyi, Nümunə Sosial Xidmətlər Nazirliyi, Vüsal Nazirliyi, Lalə Qurumu, Çinar Komitəsi, Aydın Xidməti, Təbiət Qurumu, Günəş Nazirliyi, Ulduz Agentliyi, Bulaq Şurası | H28: Əsas icraçı | I28: Dağ Qurumu, Koordinasiya şöbəsi, Aran Agentliyi, Ərgün Xidməti | J28: Digər icraçı | K28: Hüquqi akt üzrə | L28: ÇAUNF, LAÜT | S28: Elektron platformada 33 yeni məlumat təqdim edilmişdir | X28: İcra müddətinə var | Y28: Tam icra | AA28: İcra müddətinə var | AB28: Tam icra | AD28: 1
A29: 28 | B29: Respublikada ətraf mühitin mühafizəsi üzrə 2020–2025-ci illər üçün Tədbirlər Proqramı | C29: 8.4.1. | D29: İnformasiya sisteminin gücləndirilməsi | F29: Mütəmadi | G29: Bəhər Nazirliyi, Qızıl Nazirliyi, Gümüş Komitəsi, Zümrüd Xidməti, Ənvər Xidməti, Nümunə Sosial Xidmətlər Nazirliyi, Aydın Xidməti | H29: Digər icraçı | I29: Koordinasiya şöbəsi, Aran Agentliyi, İnsan resursları şöbəsi, Ərgün Xidməti | J29: Digər icraçı | K29: Hüquqi akt üzrə | L29: ÇAUNF | M29: Aparılmış monitorinqlərin sayı | N29: 4 | Q29: 1 | R29: 2 | T29: 2 | V29: 3 | X29: Qismən icra | Y29: İcra müddətinə var | AA29: Qismən icra | AB29: İcra müddətinə var | AD29: 1
A30: 29 | B30: Respublikada ətraf mühitin mühafizəsi üzrə 2020–2025-ci illər üçün Tədbirlər Proqramı | C30: 7.1.8. | D30: Pilot layihə çərçivəsində regional mərkəzlərin inkişaf etdirilməsi | F30: Mütəmadi | G30: Bəhər Nazirliyi, Nümunə Sosial Xidmətlər Nazirliyi, Gümüş Komitəsi, Zümrüd Xidməti, Aydın Xidməti, Ənvər Xidməti, digər aidiyyəti dövlət orqanları | H30: Əsas icraçı | I30: Ərgün Xidməti, Aran Agentliyi | J30: Digər icraçı | K30: Hüquqi akt üzrə | L30: ÇAUNF | X30: İcra müddətinə var | Y30: İcra müddətinə var | AA30: İcra müddətinə var | AB30: İcra müddətinə var | AD30: 1
A31: 30 | B31: Respublikada ətraf mühitin mühafizəsi üzrə 2020–2025-ci illər üçün Tədbirlər Proqramı | C31: 6.6.1. | D31: Ailələrin gücləndirilməsi | F31: Mütəmadi | G31: Bəhər Nazirliyi, Lalə Qurumu, Çinar Komitəsi, Nümunə Sosial Xidmətlər Nazirliyi, Aydın Xidməti | H31: Digər icraçı | I31: Aran Agentliyi, Koordinasiya şöbəsi | J31: Əsas icraçı | K31: Tapşırıqların İcrasına Nəzarət platforması üzrə | L31: ÇAUNF, LAÜT | M31: Aparılmış monitorinqlərin sayı | N31: 10 | P31: 1 | Q31: 1 | R31: 3 | T31: 2 | V31: 4 | X31: Tam icra | Y31: İcra müddətinə var | AA31: Tam icra | AB31: İcra müddətinə var | AD31: 1
A32: 31 | B32: Respublikada ətraf mühitin mühafizəsi üzrə 2020–2025-ci illər üçün Tədbirlər Proqramı | C32: 5.2.4. | D32: İllik plana uyğun könüllü qrupların təşkil edilməsi | F32: Mütəmadi | G32: Nümunə Sosial Xidmətlər Nazirliyi, Lalə Qurumu, Çinar Komitəsi, Vüsal Nazirliyi, Səbuhi Agentliyi, Bəhər Nazirliyi | H32: Əsas icraçı | I32: Aran Agentliyi, Koordinasiya şöbəsi | J32: Əsas icraçı | K32: Tapşırıqların İcrasına Nəzarət platforması üzrə | L32: ÇAUNF,LAÜT | M32: Yenilənmiş məlumat bazalarının sayı | N32: Hədəf qrup üzrə 9 tədbirin keçirilməsi | P32: 1 | R32: 5 | T32: 4 | V32: 4 | X32: Gecikmə | Y32: İcra olunmayıb, prioritet deyil | AA32: Gecikmə | AB32: İcra olunmayıb, prioritet deyil | AD32: 1
A33: 32 | B33: Respublikada ətraf mühitin mühafizəsi üzrə 2020–2025-ci illər üçün Tədbirlər Proqramı | C33: 6.1.7. | D33: Pilot layihə çərçivəsində məsləhətləşmə xidmətlərinin genişləndirilməsi | F33: Mütəmadi | G33: Rəhim Nazirliyi, Bəhər Nazirliyi, Aydın Xidməti, Vüsal Nazirliyi, Nümunə Sosial Xidmətlər Nazirliyi, Lalə Qurumu, Çinar Komitəsi,digər aidiyyəti dövlət orqanları | H33: Digər icraçı | I33: Aran Agentliyi, Meydan Agentliyi | J33: Əsas icraçı | K33: Tapşırıqların İcrasına Nəzarət platforması üzrə | L33: ÇAUNF | X33: Tam icra | Y33: Tam icra | AA33: Tam icra | AB33: Tam icra | AD33: 1
A34: 33 | B34: Respublikada ətraf mühitin mühafizəsi üzrə 2020–2025-ci illər üçün Tədbirlər Proqramı | C34: 3.3.6. | D34: Statistik məlumat bazasının tətbiq olunması | F34: Mütəmadi | G34: Orxan Nazirliyi, Lalə Qurumu, Çinar Komitəsi, Nümunə Sosial Xidmətlər Nazirliyi, Bəhər Nazirliyi, ixtisaslaşmış qeyri-hökumət təşkilatlarını cəlb etməklə | H34: Digər icraçı | I34: Aran Agentliyi | J34: Əsas icraçı | K34: Tapşırıqların İcrasına Nəzarət platforması üzrə | L34: ÇAUNF | M34: Hazırlanmış metodik vəsaitlərin sayı | N34: 4 | Q34: 4 | R34: 1 | T34: 2 | V34: 1 | X34: Qismən icra | Y34: İcra müddətinə var | AA34: Qismən icra | AB34: İcra müddətinə var | AD34: 1
A35: 34 | B35: Respublikada ətraf mühitin mühafizəsi üzrə 2020–2025-ci illər üçün Tədbirlər Proqramı | C35: 7.4.3. | D35: Hədəf qrup üzrə monitorinq mexanizminin davamlı olaraq həyata keçirilməsi | F35: Mütəmadi | G35: Nümunə Sosial Xidmətlər Nazirliyi, Lalə Qurumu, Çinar Komitəsi, Orxan Nazirliyi, Səbuhi Agentliyi | H35: Digər icraçı | I35: Aran Agentliyi, Meydan Agentliyi | J35: Əsas icraçı | K35: Tapşırıqların İcrasına Nəzarət platforması üzrə | L35: ÇAUNF,LAÜT | M35: Əhatə olunan şəxslərin sayı | N35: 2 | Q35: 1 | R35: 1 | S35: Hesabat dövründə 29 nəfər hədəf qrupdan tədbirlərə cəlb edilmişdir | T35: 1 | V35: 2 | X35: Tam icra | Y35: Tam icra | AA35: Tam icra | AB35: Tam icra | AD35: 1
A36: 35 | B36: Respublikada ətraf mühitin mühafizəsi üzrə 2020–2025-ci illər üçün Tədbirlər Proqramı | C36: 9.1.7. | D36: Statistik məlumat bazasının təkmilləşdirilməsi | F36: Mütəmadi | G36: Orxan Nazirliyi, Lalə Qurumu, Çinar Komitəsi, Nümunə Sosial Xidmətlər Nazirliyi, Bəhər Nazirliyi, yerli icra hakimiyyəti orqanları, aidiyyəti qeyri-hökumət təşkilatlarını cəlb etməklə | H36: Digər icraçı | I36: Koordinasiya şöbəsi, Aran Agentliyi | J36: Digər icraçı | K36: Hüquqi akt üzrə | L36: ÇAUNF | M36: Açılmış xidmət məntəqələrinin sayı | N36: 5 | P36: 1 | Q36: 5 | R36: 2 | T36: 1 | V36: 1 | X36: İcra olunmayıb, prioritet deyil | Y36: İcra müddətinə var | AA36: İcra olunmayıb, prioritet deyil | AB36: İcra müddətinə var | AD36: 1
A37: 36 | B37: Respublikada ətraf mühitin mühafizəsi üzrə 2020–2025-ci illər üçün Tədbirlər Proqramı | C37: 2.7.2. | D37: Regionlar üzrə əməkdaşlıq protokollarının gücləndirilməsi | F37: Mütəmadi | G37: Nümunə Sosial Xidmətlər Nazirliyi, Lalə Qurumu, Çinar Komitəsi, Yerli icra hakimiyyəti orqanları | H37: Əsas icraçı | I37: Monitorinq və qiymətləndirmə şöbəsi, Aran Agentliyi | J37: Digər icraçı | K37: Hüquqi akt üzrə | L37: ZCÖSÇ | Q37: 15 iştirakçının əhatə olunduğu təlim sessiyaları keçirilmişdir | S37: Planlaşdırılan işlər üzrə 8 fəaliyyət həyata keçirilmişdir | X37: Tam icra | Y37: Tam icra | AA37: Tam icra | AB37: Tam icra | AD37: 1
A38: 37 | B38: Respublikada ətraf mühitin mühafizəsi üzrə 2020–2025-ci illər üçün Tədbirlər Proqramı | C38: 9.6.8. | D38: Regionlar üzrə məsləhətləşmə xidmətlərinin tətbiq olunması | F38: Mütəmadi | G38: Bəhər Nazirliyi, Aydın Xidməti, Lalə Qurumu, Çinar Komitəsi, Nümunə Sosial Xidmətlər Nazirliyi, Orxan Nazirliyi | H38: Digər icraçı | I38: Aran Agentliyi | J38: Digər icraçı | K38: Tapşırıqların İcrasına Nəzarət platforması üzrə | L38: ÇAUNF | Q38: 7 | X38: Qismən icra | Y38: Gecikmə | AA38: Qismən icra | AB38: Gecikmə | AD38: 1
A39: 38 | B39: Respublikada ətraf mühitin mühafizəsi üzrə 2020–2025-ci illər üçün Tədbirlər Proqramı | C39: 4.3.9. | D39: Hədəf qrup üzrə icma əsaslı proqramların təkmilləşdirilməsi | F39: Mütəmadi | G39: Lalə Qurumu, Çinar Komitəsi, Nümunə Sosial Xidmətlər Nazirliyi, Orxan Nazirliyi, Vüsal Nazirliyi, Səbuhi Agentliyi, Bəhər Nazirliyi | H39: Əsas icraçı | I39: Koordinasiya şöbəsi, Aran Agentliyi, Maliyyə və təchizat şöbəsi | J39: Digər icraçı | K39: Hüquqi akt üzrə | L39: LAÜT, HZÜ | M39: Qəbul edilmiş müraciətlərin sayı | Q39: Hesabat dövründə 24 nəfər hədəf qrupdan tədbirlərə cəlb edilmişdir | S39: Hesabat dövründə 49 nəfər hədəf qrupdan tədbirlərə cəlb edilmişdir | U39: 54 | X39: Tam icra | Y39: Qismən icra | AA39: Tam icra | AB39: Qismən icra | AD39: 1
A40: 39 | B40: Respublikada ətraf mühitin mühafizəsi üzrə 2020–2025-ci illər üçün Tədbirlər Proqramı | C40: 1.2.5. | D40: Pilot layihə çərçivəsində regional mərkəzlərin inkişaf etdirilməsi | F40: Mütəmadi | G40: Bəhər Nazirliyi, Qızıl Nazirliyi, Gümüş Komitəsi, Zümrüd Xidməti, Ənvər Xidməti, Nümunə Sosial Xidmətlər Nazirliyi, Aydın Xidməti, Orxan Nazirliyi, Rəhim Nazirliyi, Lalə Qurumu, Çinar Komitəsi, Ulduz Agentliyi | H40: Digər icraçı | I40: Kəmalə Qurumu, Aran Agentliyi, Ərgün Xidməti | J40: Digər icraçı | K40: Hüquqi akt üzrə | L40: ÇAUNF | M40: Açılmış xidmət məntəqələrinin sayı | N40: 6 | P40: 2 | Q40: 1 | R40: 2 | T40: 3 | V40: 2 | X40: Tam icra | Y40: İcra müddətinə var | AA40: Tam icra | AB40: İcra müddətinə var | AD40: 1
...

Sheet Hesabat I
B1: DP N əsas TP A əsas - Dövlət Proqramı üzrə Nazirliyin əsas, Nazirliyin Tədbirlər Planı ilə Agentliyin əsas içracı olduğu bəndlər | E1: Göstərici | F1: Hüquqi aktların sayı | G1: Yarımbəndlərin sayı
B2: DP N əsas TP A digər - Dövlət Proqramı üzrə Nazirliyin əsas, Nazirliyin Tədbirlər Planı ilə Agentliyin digər içracı olduğu bəndlər | E2: Ümumi icra olunan işlər | F2: =A38 -> 28 | G2: =C39 -> 259
B3: DP N digər TP A əsas - Dövlət Proqramı üzrə Nazirliyin digər, Nazirliyin Tədbirlər Planı ilə Agentliyin əsas içracı olduğu bəndlər | E3: Əsas icraçı olduğumuz | F3: 16 | G3: =COUNTIFS('DP və TP'!J:J,"Əsas icraçı",'DP və TP'!$AD:$AD,"<=1") -> 115
B4: DP N digər TP A digər - Dövlət Proqramı üzrə Nazirliyin digər, Nazirliyin Tədbirlər Planı ilə Agentliyin digər içracı olduğu bəndlər | E4: Digər icraçı olduğumuz | F4: 18 | G4: =COUNTIFS('DP və TP'!J:J,"Digər icraçı",'DP və TP'!$AD:$AD,"<=1") -> 144
B5: Tin üzrə - Tapşırıqların İcrasına Nəzarət platformasında olan bəndlər
A9: Sıra № | B9: Hüquqi Aktın adı | C9: İcra olunmalı yarımbənd sayı | D9: Hüquqi Akt üzrə icra vəziyyəti | J9: Tin üzrə icra vəziyyəti
D10: Tam icra | E10: Qismən icra | F10: İcra müddətinə var | G10: Gecikmə | H10: İcra olunmayıb | I10: İcra olunmayıb, prioritet deyil | J10: Tam icra | K10: Qismən icra | L10: İcra müddətinə var | M10: Gecikmə | N10: İcra olunmayıb | O10: İcra olunmayıb, prioritet deyil | P10: CƏMİ
A11: 1 | B11: “Respublikada regional inkişaf üzrə 2024–2029-ci illər üçün Dövlət Proqramı” | C11: =COUNTIFS('DP və TP'!$B:$B,B11,'DP və TP'!$AD:$AD,"<=1") -> 9 | D11: =COUNTIFS('DP və TP'!$B:$B,B11,'DP və TP'!$X:$X,"Tam icra",'DP və TP'!$AD:$AD,"<=1") -> 6 | E11: =COUNTIFS('DP və TP'!$B:$B,B11, 'DP və TP'!$X:$X,"Qismən icra",'DP və TP'!$AD:$AD,"<=1") -> 0 | F11: =COUNTIFS('DP və TP'!$B:$B,B11, 'DP və TP'!$X:$X,"İcra müddətinə var",'DP və TP'!$AD:$AD,"<=1") -> 3 | G11: =COUNTIFS('DP və TP'!$B:$B,B11, 'DP və TP'!$X:$X,"Gecikmə",'DP və TP'!$AD:$AD,"<=1") -> 0 | H11: =COUNTIFS('DP və TP'!$B:$B,B11, 'DP və TP'!$X:$X,"İcra olunmayıb",'DP və TP'!$AD:$AD,"<=1") -> 0 | I11: =COUNTIFS('DP və TP'!$B:$B,B11, 'DP və TP'!$X:$X,"İcra olunmayıb, prioritet deyil",'DP və TP'!$AD:$AD,"<=1") -> 0 | J11: =COUNTIFS('DP və TP'!$B:$B,B11, 'DP və TP'!$K:$K,"Tapşırıqların İcrasına Nəzarət platforması üzrə", 'DP və TP'!$X:$X,"Tam icra",'DP və TP'!$AD:$AD,"<=1") -> 1 | K11: =COUNTIFS('DP və TP'!$B:$B,B11, 'DP və TP'!$K:$K,"Tapşırıqların İcrasına Nəzarət platforması üzrə", 'DP və TP'!$X:$X,"Qismən icra",'DP və TP'!$AD:$AD,"<=1") -> 0 | L11: =COUNTIFS('DP və TP'!$B:$B,B11, 'DP və TP'!$K:$K,"Tapşırıqların İcrasına Nəzarət platforması üzrə", 'DP və TP'!$X:$X,"İcra müddətinə var",'DP və TP'!$AD:$AD,"<=1") -> 1 | M11: =COUNTIFS('DP və TP'!$B:$B,B11, 'DP və TP'!$K:$K,"Tapşırıqların İcrasına Nəzarət platforması üzrə", 'DP və TP'!$X:$X,"Gecikmə",'DP və TP'!$AD:$AD,"<=1") -> 0 | N11: =COUNTIFS('DP və TP'!$B:$B,B11, 'DP və TP'!$K:$K,"Tapşırıqların İcrasına Nəzarət platforması üzrə", 'DP və TP'!$X:$X,"İcra olunmayıb",'DP və TP'!$AD:$AD,"<=1") -> 0 | O11: =COUNTIFS('DP və TP'!$B:$B,B11, 'DP və TP'!$K:$K,"Tapşırıqların İcrasına Nəzarət platforması üzrə", 'DP və TP'!$X:$X,"İcra olunmayıb, prioritet deyil",'DP və TP'!$AD:$AD,"<=1") -> 0 | P11: =SUM(J11:O11) -> 2
A12: 2 | B12: Respublikada mədəni irsin qorunması üzrə 2025–2030-ci illər üçün Milli Fəaliyyət Planı | C12: =COUNTIFS('DP və TP'!$B:$B,B12,'DP və TP'!$AD:$AD,"<=1") -> 4 | D12: =COUNTIFS('DP və TP'!$B:$B,B12,'DP və TP'!$X:$X,"Tam icra",'DP və TP'!$AD:$AD,"<=1") -> 0 | E12: =COUNTIFS('DP və TP'!$B:$B,B12, 'DP və TP'!$X:$X,"Qismən icra",'DP və TP'!$AD:$AD,"<=1") -> 0 | F12: =COUNTIFS('DP və TP'!$B:$B,B12, 'DP və TP'!$X:$X,"İcra müddətinə var",'DP və TP'!$AD:$AD,"<=1") -> 2 | G12: =COUNTIFS('DP və TP'!$B:$B,B12, 'DP və TP'!$X:$X,"Gecikmə",'DP və TP'!$AD:$AD,"<=1") -> 0 | H12: =COUNTIFS('DP və TP'!$B:$B,B12, 'DP və TP'!$X:$X,"İcra olunmayıb",'DP və TP'!$AD:$AD,"<=1") -> 1 | I12: =COUNTIFS('DP və TP'!$B:$B,B12, 'DP və TP'!$X:$X,"İcra olunmayıb, prioritet deyil",'DP və TP'!$AD:$AD,"<=1") -> 1 | J12: =COUNTIFS('DP və TP'!$B:$B,B12, 'DP və TP'!$K:$K,"Tapşırıqların İcrasına Nəzarət platforması üzrə", 'DP və TP'!$X:$X,"Tam icra",'DP və TP'!$AD:$AD,"<=1") -> 0 | K12: =COUNTIFS('DP və TP'!$B:$B,B12, 'DP və TP'!$K:$K,"Tapşırıqların İcrasına Nəzarət platforması üzrə", 'DP və TP'!$X:$X,"Qismən icra",'DP və TP'!$AD:$AD,"<=1") -> 0 | L12: =COUNTIFS('DP və TP'!$B:$B,B12, 'DP və TP'!$K:$K,"Tapşırıqların İcrasına Nəzarət platforması üzrə", 'DP və TP'!$X:$X,"İcra müddətinə var",'DP və TP'!$AD:$AD,"<=1") -> 1 | M12: =COUNTIFS('DP və TP'!$B:$B,B12, 'DP və TP'!$K:$K,"Tapşırıqların İcrasına Nəzarət platforması üzrə", 'DP və TP'!$X:$X,"Gecikmə",'DP və TP'!$AD:$AD,"<=1") -> 0 | N12: =COUNTIFS('DP və TP'!$B:$B,B12, 'DP və TP'!$K:$K,"Tapşırıqların İcrasına Nəzarət platforması üzrə", 'DP və TP'!$X:$X,"İcra olunmayıb",'DP və TP'!$AD:$AD,"<=1") -> 0 | O12: =COUNTIFS('DP və TP'!$B:$B,B12, 'DP və TP'!$K:$K,"Tapşırıqların İcrasına Nəzarət platforması üzrə", 'DP və TP'!$X:$X,"İcra olunmayıb, prioritet deyil",'DP və TP'!$AD:$AD,"<=1") -> 1
A13: 3 | B13: “Respublikada sağlam həyat tərzinin təbliği üzrə 2022–2026-ci illər üçün Milli Fəaliyyət Planı” | C13: =COUNTIFS('DP və TP'!$B:$B,B13,'DP və TP'!$AD:$AD,"<=1") -> 1 | D13: =COUNTIFS('DP və TP'!$B:$B,B13,'DP və TP'!$X:$X,"Tam icra",'DP və TP'!$AD:$AD,"<=1") -> 0 | E13: =COUNTIFS('DP və TP'!$B:$B,B13, 'DP və TP'!$X:$X,"Qismən icra",'DP və TP'!$AD:$AD,"<=1") -> 0 | F13: =COUNTIFS('DP və TP'!$B:$B,B13, 'DP və TP'!$X:$X,"İcra müddətinə var",'DP və TP'!$AD:$AD,"<=1") -> 1 | G13: =COUNTIFS('DP və TP'!$B:$B,B13, 'DP və TP'!$X:$X,"Gecikmə",'DP və TP'!$AD:$AD,"<=1") -> 0 | H13: =COUNTIFS('DP və TP'!$B:$B,B13, 'DP və TP'!$X:$X,"İcra olunmayıb",'DP və TP'!$AD:$AD,"<=1") -> 0 | I13: =COUNTIFS('DP və TP'!$B:$B,B13, 'DP və TP'!$X:$X,"İcra olunmayıb, prioritet deyil",'DP və TP'!$AD:$AD,"<=1") -> 0 | J13: =COUNTIFS('DP və TP'!$B:$B,B13, 'DP və TP'!$K:$K,"Tapşırıqların İcrasına Nəzarət platforması üzrə", 'DP və TP'!$X:$X,"Tam icra",'DP və TP'!$AD:$AD,"<=1") -> 0 | K13: =COUNTIFS('DP və TP'!$B:$B,B13, 'DP və TP'!$K:$K,"Tapşırıqların İcrasına Nəzarət platforması üzrə", 'DP və TP'!$X:$X,"Qismən icra",'DP və TP'!$AD:$AD,"<=1") -> 0 | L13: =COUNTIFS('DP və TP'!$B:$B,B13, 'DP və TP'!$K:$K,"Tapşırıqların İcrasına Nəzarət platforması üzrə", 'DP və TP'!$X:$X,"İcra müddətinə var",'DP və TP'!$AD:$AD,"<=1") -> 1 | M13: =COUNTIFS('DP və TP'!$B:$B,B13, 'DP və TP'!$K:$K,"Tapşırıqların İcrasına Nəzarət platforması üzrə", 'DP və TP'!$X:$X,"Gecikmə",'DP və TP'!$AD:$AD,"<=1") -> 0 | N13: =COUNTIFS('DP və TP'!$B:$B,B13, 'DP və TP'!$K:$K,"Tapşırıqların İcrasına Nəzarət platforması üzrə", 'DP və TP'!$X:$X,"İcra olunmayıb",'DP və TP'!$AD:$AD,"<=1") -> 0 | O13: =COUNTIFS('DP və TP'!$B:$B,B13, 'DP və TP'!$K:$K,"Tapşırıqların İcrasına Nəzarət platforması üzrə", 'DP və TP'!$X:$X,"İcra olunmayıb, prioritet deyil",'DP və TP'!$AD:$AD,"<=1") -> 0 | P13: =SUM(J13:O13) -> 1
A14: 4 | B14: Respublikada təhsilə çıxışın genişləndirilməsi üzrə 2024–2029-ci illər üçün Strategiyanın həyata keçirilməsi üzrə Tədbirlər Planı | C14: =COUNTIFS('DP və TP'!$B:$B,B14,'DP və TP'!$AD:$AD,"<=1") -> 6 | D14: =COUNTIFS('DP və TP'!$B:$B,B14,'DP və TP'!$X:$X,"Tam icra",'DP və TP'!$AD:$AD,"<=1") -> 0 | E14: =COUNTIFS('DP və TP'!$B:$B,B14, 'DP və TP'!$X:$X,"Qismən icra",'DP və TP'!$AD:$AD,"<=1") -> 1 | F14: =COUNTIFS('DP və TP'!$B:$B,B14, 'DP və TP'!$X:$X,"İcra müddətinə var",'DP və TP'!$AD:$AD,"<=1") -> 3 | G14: =COUNTIFS('DP və TP'!$B:$B,B14, 'DP və TP'!$X:$X,"Gecikmə",'DP və TP'!$AD:$AD,"<=1") -> 1 | H14: =COUNTIFS('DP və TP'!$B:$B,B14, 'DP və TP'!$X:$X,"İcra olunmayıb",'DP və TP'!$AD:$AD,"<=1") -> 0 | I14: =COUNTIFS('DP və TP'!$B:$B,B14, 'DP və TP'!$X:$X,"İcra olunmayıb, prioritet deyil",'DP və TP'!$AD:$AD,"<=1") -> 1 | J14: =COUNTIFS('DP və TP'!$B:$B,B14, 'DP və TP'!$K:$K,"Tapşırıqların İcrasına Nəzarət platforması üzrə", 'DP və TP'!$X:$X,"Tam icra",'DP və TP'!$AD:$AD,"<=1") -> 0 | K14: =COUNTIFS('DP və TP'!$B:$B,B14, 'DP və TP'!$K:$K,"Tapşırıqların İcrasına Nəzarət platforması üzrə", 'DP və TP'!$X:$X,"Qismən icra",'DP və TP'!$AD:$AD,"<=1") -> 0 | L14: =COUNTIFS('DP və TP'!$B:$B,B14, 'DP və TP'!$K:$K,"Tapşırıqların İcrasına Nəzarət platforması üzrə", 'DP və TP'!$X:$X,"İcra müddətinə var",'DP və TP'!$AD:$AD,"<=1") -> 0 | M14: =COUNTIFS('DP və TP'!$B:$B,B14, 'DP və TP'!$K:$K,"Tapşırıqların İcrasına Nəzarət platforması üzrə", 'DP və TP'!$X:$X,"Gecikmə",'DP və TP'!$AD:$AD,"<=1") -> 0 | N14: =COUNTIFS('DP və TP'!$B:$B,B14, 'DP və TP'!$K:$K,"Tapşırıqların İcrasına Nəzarət platforması üzrə", 'DP və TP'!$X:$X,"İcra olunmayıb",'DP və TP'!$AD:$AD,"<=1") -> 0 | O14: =COUNTIFS('DP və TP'!$B:$B,B14, 'DP və TP'!$K:$K,"Tapşırıqların İcrasına Nəzarət platforması üzrə", 'DP və TP'!$X:$X,"İcra olunmayıb, prioritet deyil",'DP və TP'!$AD:$AD,"<=1") -> 0 | P14: =SUM(J14:O14) -> 0
A15: 5 | B15: “Respublikada yaşlı vətəndaşların sosial dəstəyi üzrə 2023–2025-ci illər üçün Konsepsiyanın icrası üzrə Fəaliyyət Planı” | C15: =COUNTIFS('DP və TP'!$B:$B,B15,'DP və TP'!$AD:$AD,"<=1") -> 2 | D15: =COUNTIFS('DP və TP'!$B:$B,B15,'DP və TP'!$X:$X,"Tam icra",'DP və TP'!$AD:$AD,"<=1") -> 1 | E15: =COUNTIFS('DP və TP'!$B:$B,B15, 'DP və TP'!$X:$X,"Qismən icra",'DP və TP'!$AD:$AD,"<=1") -> 0 | F15: =COUNTIFS('DP və TP'!$B:$B,B15, 'DP və TP'!$X:$X,"İcra müddətinə var",'DP və TP'!$AD:$AD,"<=1") -> 0 | G15: =COUNTIFS('DP və TP'!$B:$B,B15, 'DP və TP'!$X:$X,"Gecikmə",'DP və TP'!$AD:$AD,"<=1") -> 0 | H15: =COUNTIFS('DP və TP'!$B:$B,B15, 'DP və TP'!$X:$X,"İcra olunmayıb",'DP və TP'!$AD:$AD,"<=1") -> 0 | I15: =COUNTIFS('DP və TP'!$B:$B,B15, 'DP və TP'!$X:$X,"İcra olunmayıb, prioritet deyil",'DP və TP'!$AD:$AD,"<=1") -> 1 | J15: =COUNTIFS('DP və TP'!$B:$B,B15, 'DP və TP'!$K:$K,"Tapşırıqların İcrasına Nəzarət platforması üzrə", 'DP və TP'!$X:$X,"Tam icra",'DP və TP'!$AD:$AD,"<=1") -> 1 | K15: =COUNTIFS('DP və TP'!$B:$B,B15, 'DP və TP'!$K:$K,"Tapşırıqların İcrasına Nəzarət platforması üzrə", 'DP və TP'!$X:$X,"Qismən icra",'DP və TP'!$AD:$AD,"<=1") -> 0 | L15: =COUNTIFS('DP və TP'!$B:$B,B15, 'DP və TP'!$K:$K,"Tapşırıqların İcrasına Nəzarət platforması üzrə", 'DP və TP'!$X:$X,"İcra müddətinə var",'DP və TP'!$AD:$AD,"<=1") -> 0 | M15: =COUNTIFS('DP və TP'!$B:$B,B15, 'DP və TP'!$K:$K,"Tapşırıqların İcrasına Nəzarət platforması üzrə", 'DP və TP'!$X:$X,"Gecikmə",'DP və TP'!$AD:$AD,"<=1") -> 0 | N15: =COUNTIFS('DP və TP'!$B:$B,B15, 'DP və TP'!$K:$K,"Tapşırıqların İcrasına Nəzarət platforması üzrə", 'DP və TP'!$X:$X,"İcra olunmayıb",'DP və TP'!$AD:$AD,"<=1") -> 0 | O15: =COUNTIFS('DP və TP'!$B:$B,B15, 'DP və TP'!$K:$K,"Tapşırıqların İcrasına Nəzarət platforması üzrə", 'DP və TP'!$X:$X,"İcra olunmayıb, prioritet deyil",'DP və TP'!$AD:$AD,"<=1") -> 0 | P15: =SUM(J15:O15) -> 1
A16: 6 | B16: Respublikada məlumat təhlükəsizliyinin gücləndirilməsi üzrə 2025–2027-ci illər üçün Dövlət Proqramı | C16: =COUNTIFS('DP və TP'!$B:$B,B16,'DP və TP'!$AD:$AD,"<=1") -> 4 | D16: =COUNTIFS('DP və TP'!$B:$B,B16,'DP və TP'!$X:$X,"Tam icra",'DP və TP'!$AD:$AD,"<=1") -> 0 | E16: =COUNTIFS('DP və TP'!$B:$B,B16, 'DP və TP'!$X:$X,"Qismən icra",'DP və TP'!$AD:$AD,"<=1") -> 0 | F16: =COUNTIFS('DP və TP'!$B:$B,B16, 'DP və TP'!$X:$X,"İcra müddətinə var",'DP və TP'!$AD:$AD,"<=1") -> 2 | G16: =COUNTIFS('DP və TP'!$B:$B,B16, 'DP və TP'!$X:$X,"Gecikmə",'DP və TP'!$AD:$AD,"<=1") -> 2 | H16: =COUNTIFS('DP və TP'!$B:$B,B16, 'DP və TP'!$X:$X,"İcra olunmayıb",'DP və TP'!$AD:$AD,"<=1") -> 0 | I16: =COUNTIFS('DP və TP'!$B:$B,B16, 'DP və TP'!$X:$X,"İcra olunmayıb, prioritet deyil",'DP və TP'!$AD:$AD,"<=1") -> 0 | J16: =COUNTIFS('DP və TP'!$B:$B,B16, 'DP və TP'!$K:$K,"Tapşırıqların İcrasına Nəzarət platforması üzrə", 'DP və TP'!$X:$X,"Tam icra",'DP və TP'!$AD:$AD,"<=1") -> 0 | K16: =COUNTIFS('DP və TP'!$B:$B,B16, 'DP və TP'!$K:$K,"Tapşırıqların İcrasına Nəzarət platforması üzrə", 'DP və TP'!$X:$X,"Qismən icra",'DP və TP'!$AD:$AD,"<=1") -> 0 | L16: =COUNTIFS('DP və TP'!$B:$B,B16, 'DP və TP'!$K:$K,"Tapşırıqların İcrasına Nəzarət platforması üzrə", 'DP və TP'!$X:$X,"İcra müddətinə var",'DP və TP'!$AD:$AD,"<=1") -> 0 | M16: =COUNTIFS('DP və TP'!$B:$B,B16, 'DP və TP'!$K:$K,"Tapşırıqların İcrasına Nəzarət platforması üzrə", 'DP və TP'!$X:$X,"Gecikmə",'DP və TP'!$AD:$AD,"<=1") -> 0 | N16: =COUNTIFS('DP və TP'!$B:$B,B16, 'DP və TP'!$K:$K,"Tapşırıqların İcrasına Nəzarət platforması üzrə", 'DP və TP'!$X:$X,"İcra olunmayıb",'DP və TP'!$AD:$AD,"<=1") -> 0 | O16: =COUNTIFS('DP və TP'!$B:$B,B16, 'DP və TP'!$K:$K,"Tapşırıqların İcrasına Nəzarət platforması üzrə", 'DP və TP'!$X:$X,"İcra olunmayıb, prioritet deyil",'DP və TP'!$AD:$AD,"<=1") -> 0 | P16: =SUM(J16:O16) -> 0
A17: 7 | B17: Respublikada gender bərabərliyinin təmin olunması üzrə 2023–2027-ci illər üçün Dövlət Proqramı | C17: =COUNTIFS('DP və TP'!$B:$B,B17,'DP və TP'!$AD:$AD,"<=1") -> 3 | D17: =COUNTIFS('DP və TP'!$B:$B,B17,'DP və TP'!$X:$X,"Tam icra",'DP və TP'!$AD:$AD,"<=1") -> 3 | E17: =COUNTIFS('DP və TP'!$B:$B,B17, 'DP və TP'!$X:$X,"Qismən icra",'DP və TP'!$AD:$AD,"<=1") -> 0 | F17: =COUNTIFS('DP və TP'!$B:$B,B17, 'DP və TP'!$X:$X,"İcra müddətinə var",'DP və TP'!$AD:$AD,"<=1") -> 0 | G17: =COUNTIFS('DP və TP'!$B:$B,B17, 'DP və TP'!$X:$X,"Gecikmə",'DP və TP'!$AD:$AD,"<=1") -> 0 | H17: =COUNTIFS('DP və TP'!$B:$B,B17, 'DP və TP'!$X:$X,"İcra olunmayıb",'DP və TP'!$AD:$AD,"<=1") -> 0 | I17: =COUNTIFS('DP və TP'!$B:$B,B17, 'DP və TP'!$X:$X,"İcra olunmayıb, prioritet deyil",'DP və TP'!$AD:$AD,"<=1") -> 0 | J17: =COUNTIFS('DP və TP'!$B:$B,B17, 'DP və TP'!$K:$K,"Tapşırıqların İcrasına Nəzarət platforması üzrə", 'DP və TP'!$X:$X,"Tam icra",'DP və TP'!$AD:$AD,"<=1") -> 2 | K17: =COUNTIFS('DP və TP'!$B:$B,B17, 'DP və TP'!$K:$K,"Tapşırıqların İcrasına Nəzarət platforması üzrə", 'DP və TP'!$X:$X,"Qismən icra",'DP və TP'!$AD:$AD,"<=1") -> 0 | L17: =COUNTIFS('DP və TP'!$B:$B,B17, 'DP və TP'!$K:$K,"Tapşırıqların İcrasına Nəzarət platforması üzrə", 'DP və TP'!$X:$X,"İcra müddətinə var",'DP və TP'!$AD:$AD,"<=1") -> 0 | M17: =COUNTIFS('DP və TP'!$B:$B,B17, 'DP və TP'!$K:$K,"Tapşırıqların İcrasına Nəzarət platforması üzrə", 'DP və TP'!$X:$X,"Gecikmə",'DP və TP'!$AD:$AD,"<=1") -> 0 | N17: =COUNTIFS('DP və TP'!$B:$B,B17, 'DP və TP'!$K:$K,"Tapşırıqların İcrasına Nəzarət platforması üzrə", 'DP və TP'!$X:$X,"İcra olunmayıb",'DP və TP'!$AD:$AD,"<=1") -> 0 | O17: =COUNTIFS('DP və TP'!$B:$B,B17, 'DP və TP'!$K:$K,"Tapşırıqların İcrasına Nəzarət platforması üzrə", 'DP və TP'!$X:$X,"İcra olunmayıb, prioritet deyil",'DP və TP'!$AD:$AD,"<=1") -> 0 | P17: =SUM(J17:O17) -> 2
A18: 8 | B18: Respublikada icma əsaslı xidmətlərin inkişafı üzrə 2023–2026-ci illər üçün Konsepsiyanın icrası üzrə Fəaliyyət Planı | C18: =COUNTIFS('DP və TP'!$B:$B,B18,'DP və TP'!$AD:$AD,"<=1") -> 1 | D18: =COUNTIFS('DP və TP'!$B:$B,B18,'DP və TP'!$X:$X,"Tam icra",'DP və TP'!$AD:$AD,"<=1") -> 0 | E18: =COUNTIFS('DP və TP'!$B:$B,B18, 'DP və TP'!$X:$X,"Qismən icra",'DP və TP'!$AD:$AD,"<=1") -> 0 | F18: =COUNTIFS('DP və TP'!$B:$B,B18, 'DP və TP'!$X:$X,"İcra müddətinə var",'DP və TP'!$AD:$AD,"<=1") -> 0 | G18: =COUNTIFS('DP və TP'!$B:$B,B18, 'DP və TP'!$X:$X,"Gecikmə",'DP və TP'!$AD:$AD,"<=1") -> 0 | H18: =COUNTIFS('DP və TP'!$B:$B,B18, 'DP və TP'!$X:$X,"İcra olunmayıb",'DP və TP'!$AD:$AD,"<=1") -> 0 | I18: =COUNTIFS('DP və TP'!$B:$B,B18, 'DP və TP'!$X:$X,"İcra olunmayıb, prioritet deyil",'DP və TP'!$AD:$AD,"<=1") -> 1 | J18: =COUNTIFS('DP və TP'!$B:$B,B18, 'DP və TP'!$K:$K,"Tapşırıqların İcrasına Nəzarət platforması üzrə", 'DP və TP'!$X:$X,"Tam icra",'DP və TP'!$AD:$AD,"<=1") -> 0 | K18: =COUNTIFS('DP və TP'!$B:$B,B18, 'DP və TP'!$K:$K,"Tapşırıqların İcrasına Nəzarət platforması üzrə", 'DP və TP'!$X:$X,"Qismən icra",'DP və TP'!$AD:$AD,"<=1") -> 0 | L18: =COUNTIFS('DP və TP'!$B:$B,B18, 'DP və TP'!$K:$K,"Tapşırıqların İcrasına Nəzarət platforması üzrə", 'DP və TP'!$X:$X,"İcra müddətinə var",'DP və TP'!$AD:$AD,"<=1") -> 0 | M18: =COUNTIFS('DP və TP'!$B:$B,B18, 'DP və TP'!$K:$K,"Tapşırıqların İcrasına Nəzarət platforması üzrə", 'DP və TP'!$X:$X,"Gecikmə",'DP və TP'!$AD:$AD,"<=1") -> 0 | N18: =COUNTIFS('DP və TP'!$B:$B,B18, 'DP və TP'!$K:$K,"Tapşırıqların İcrasına Nəzarət platforması üzrə", 'DP və TP'!$X:$X,"İcra olunmayıb",'DP və TP'!$AD:$AD,"<=1") -> 0 | O18: =COUNTIFS('DP və TP'!$B:$B,B18, 'DP və TP'!$K:$K,"Tapşırıqların İcrasına Nəzarət platforması üzrə", 'DP və TP'!$X:$X,"İcra olunmayıb, prioritet deyil",'DP və TP'!$AD:$AD,"<=1") -> 0 | P18: =SUM(J18:O18) -> 0
A19: 9 | B19: Respublikada inklüziv mühitin yaradılması üzrə 2025–2030-ci illər üçün Konsepsiyanın icrası üzrə Fəaliyyət Planı | C19: =COUNTIFS('DP və TP'!$B:$B,B19,'DP və TP'!$AD:$AD,"<=1") -> 1 | D19: =COUNTIFS('DP və TP'!$B:$B,B19,'DP və TP'!$X:$X,"Tam icra",'DP və TP'!$AD:$AD,"<=1") -> 0 | E19: =COUNTIFS('DP və TP'!$B:$B,B19, 'DP və TP'!$X:$X,"Qismən icra",'DP və TP'!$AD:$AD,"<=1") -> 0 | F19: =COUNTIFS('DP və TP'!$B:$B,B19, 'DP və TP'!$X:$X,"İcra müddətinə var",'DP və TP'!$AD:$AD,"<=1") -> 0 | G19: =COUNTIFS('DP və TP'!$B:$B,B19, 'DP və TP'!$X:$X,"Gecikmə",'DP və TP'!$AD:$AD,"<=1") -> 0 | H19: =COUNTIFS('DP və TP'!$B:$B,B19, 'DP və TP'!$X:$X,"İcra olunmayıb",'DP və TP'!$AD:$AD,"<=1") -> 1 | I19: =COUNTIFS('DP və TP'!$B:$B,B19, 'DP və TP'!$X:$X,"İcra olunmayıb, prioritet deyil",'DP və TP'!$AD:$AD,"<=1") -> 0 | J19: =COUNTIFS('DP və TP'!$B:$B,B19, 'DP və TP'!$K:$K,"Tapşırıqların İcrasına Nəzarət platforması üzrə", 'DP və TP'!$X:$X,"Tam icra",'DP və TP'!$AD:$AD,"<=1") -> 0 | K19: =COUNTIFS('DP və TP'!$B:$B,B19, 'DP və TP'!$K:$K,"Tapşırıqların İcrasına Nəzarət platforması üzrə", 'DP və TP'!$X:$X,"Qismən icra",'DP və TP'!$AD:$AD,"<=1") -> 0 | L19: =COUNTIFS('DP və TP'!$B:$B,B19, 'DP və TP'!$K:$K,"Tapşırıqların İcrasına Nəzarət platforması üzrə", 'DP və TP'!$X:$X,"İcra müddətinə var",'DP və TP'!$AD:$AD,"<=1") -> 0 | M19: =COUNTIFS('DP və TP'!$B:$B,B19, 'DP və TP'!$K:$K,"Tapşırıqların İcrasına Nəzarət platforması üzrə", 'DP və TP'!$X:$X,"Gecikmə",'DP və TP'!$AD:$AD,"<=1") -> 0 | N19: =COUNTIFS('DP və TP'!$B:$B,B19, 'DP və TP'!$K:$K,"Tapşırıqların İcrasına Nəzarət platforması üzrə", 'DP və TP'!$X:$X,"İcra olunmayıb",'DP və TP'!$AD:$AD,"<=1") -> 1 | O19: =COUNTIFS('DP və TP'!$B:$B,B19, 'DP və TP'!$K:$K,"Tapşırıqların İcrasına Nəzarət platforması üzrə", 'DP və TP'!$X:$X,"İcra olunmayıb, prioritet deyil",'DP və TP'!$AD:$AD,"<=1") -> 0 | P19: =SUM(J19:O19) -> 1
A20: 10 | B20: Respublikada peşə hazırlığının təkmilləşdirilməsi üzrə 2019–2021-ci illər üçün Milli Fəaliyyət Planı | C20: =COUNTIFS('DP və TP'!$B:$B,B20,'DP və TP'!$AD:$AD,"<=1") -> 3 | D20: =COUNTIFS('DP və TP'!$B:$B,B20,'DP və TP'!$X:$X,"Tam icra",'DP və TP'!$AD:$AD,"<=1") -> 0 | E20: =COUNTIFS('DP və TP'!$B:$B,B20, 'DP və TP'!$X:$X,"Qismən icra",'DP və TP'!$AD:$AD,"<=1") -> 0 | F20: =COUNTIFS('DP və TP'!$B:$B,B20, 'DP və TP'!$X:$X,"İcra müddətinə var",'DP və TP'!$AD:$AD,"<=1") -> 2 | G20: =COUNTIFS('DP və TP'!$B:$B,B20, 'DP və TP'!$X:$X,"Gecikmə",'DP və TP'!$AD:$AD,"<=1") -> 1 | H20: =COUNTIFS('DP və TP'!$B:$B,B20, 'DP və TP'!$X:$X,"İcra olunmayıb",'DP və TP'!$AD:$AD,"<=1") -> 0 | I20: =COUNTIFS('DP və TP'!$B:$B,B20, 'DP və TP'!$X:$X,"İcra olunmayıb, prioritet deyil",'DP və TP'!$AD:$AD,"<=1") -> 0 | J20: =COUNTIFS('DP və TP'!$B:$B,B20, 'DP və TP'!$K:$K,"Tapşırıqların İcrasına Nəzarət platforması üzrə", 'DP və TP'!$X:$X,"Tam icra",'DP və TP'!$AD:$AD,"<=1") -> 0 | K20: =COUNTIFS('DP və TP'!$B:$B,B20, 'DP və TP'!$K:$K,"Tapşırıqların İcrasına Nəzarət platforması üzrə", 'DP və TP'!$X:$X,"Qismən icra",'DP və TP'!$AD:$AD,"<=1") -> 0 | L20: =COUNTIFS('DP və TP'!$B:$B,B20, 'DP və TP'!$K:$K,"Tapşırıqların İcrasına Nəzarət platforması üzrə", 'DP və TP'!$X:$X,"İcra müddətinə var",'DP və TP'!$AD:$AD,"<=1") -> 2 | M20: =COUNTIFS('DP və TP'!$B:$B,B20, 'DP və TP'!$K:$K,"Tapşırıqların İcrasına Nəzarət platforması üzrə", 'DP və TP'!$X:$X,"Gecikmə",'DP və TP'!$AD:$AD,"<=1") -> 1 | N20: =COUNTIFS('DP və TP'!$B:$B,B20, 'DP və TP'!$K:$K,"Tapşırıqların İcrasına Nəzarət platforması üzrə", 'DP və TP'!$X:$X,"İcra olunmayıb",'DP və TP'!$AD:$AD,"<=1") -> 0 | O20: =COUNTIFS('DP və TP'!$B:$B,B20, 'DP və TP'!$K:$K,"Tapşırıqların İcrasına Nəzarət platforması üzrə", 'DP və TP'!$X:$X,"İcra olunmayıb, prioritet deyil",'DP və TP'!$AD:$AD,"<=1") -> 0 | P20: =SUM(J20:O20) -> 3
A21: 11 | B21: “Respublikada kənd yerlərində xidmətlərin əlçatanlığı üzrə 2025–2027-ci illər üçün Dövlət Proqramı” | C21: =COUNTIFS('DP və TP'!$B:$B,B21,'DP və TP'!$AD:$AD,"<=1") -> 3 | D21: =COUNTIFS('DP və TP'!$B:$B,B21,'DP və TP'!$X:$X,"Tam icra",'DP və TP'!$AD:$AD,"<=1") -> 0 | E21: =COUNTIFS('DP və TP'!$B:$B,B21, 'DP və TP'!$X:$X,"Qismən icra",'DP və TP'!$AD:$AD,"<=1") -> 1 | F21: =COUNTIFS('DP və TP'!$B:$B,B21, 'DP və TP'!$X:$X,"İcra müddətinə var",'DP və TP'!$AD:$AD,"<=1") -> 2 | G21: =COUNTIFS('DP və TP'!$B:$B,B21, 'DP və TP'!$X:$X,"Gecikmə",'DP və TP'!$AD:$AD,"<=1") -> 0 | H21: =COUNTIFS('DP və TP'!$B:$B,B21, 'DP və TP'!$X:$X,"İcra olunmayıb",'DP və TP'!$AD:$AD,"<=1") -> 0 | I21: =COUNTIFS('DP və TP'!$B:$B,B21, 'DP və TP'!$X:$X,"İcra olunmayıb, prioritet deyil",'DP və TP'!$AD:$AD,"<=1") -> 0 | J21: =COUNTIFS('DP və TP'!$B:$B,B21, 'DP və TP'!$K:$K,"Tapşırıqların İcrasına Nəzarət platforması üzrə", 'DP və TP'!$X:$X,"Tam icra",'DP və TP'!$AD:$AD,"<=1") -> 0 | K21: =COUNTIFS('DP və TP'!$B:$B,B21, 'DP və TP'!$K:$K,"Tapşırıqların İcrasına Nəzarət platforması üzrə", 'DP və TP'!$X:$X,"Qismən icra",'DP və TP'!$AD:$AD,"<=1") -> 0 | L21: =COUNTIFS('DP və TP'!$B:$B,B21, 'DP və TP'!$K:$K,"Tapşırıqların İcrasına Nəzarət platforması üzrə", 'DP və TP'!$X:$X,"İcra müddətinə var",'DP və TP'!$AD:$AD,"<=1") -> 0 | M21: =COUNTIFS('DP və TP'!$B:$B,B21, 'DP və TP'!$K:$K,"Tapşırıqların İcrasına Nəzarət platforması üzrə", 'DP və TP'!$X:$X,"Gecikmə",'DP və TP'!$AD:$AD,"<=1") -> 0 | N21: =COUNTIFS('DP və TP'!$B:$B,B21, 'DP və TP'!$K:$K,"Tapşırıqların İcrasına Nəzarət platforması üzrə", 'DP və TP'!$X:$X,"İcra olunmayıb",'DP və TP'!$AD:$AD,"<=1") -> 0 | O21: =COUNTIFS('DP və TP'!$B:$B,B21, 'DP və TP'!$K:$K,"Tapşırıqların İcrasına Nəzarət platforması üzrə", 'DP və TP'!$X:$X,"İcra olunmayıb, prioritet deyil",'DP və TP'!$AD:$AD,"<=1") -> 0
A22: 12 | B22: Respublikada ictimai təhlükəsizliyin təmin edilməsi üzrə 2023–2027-ci illər üçün Tədbirlər Proqramı | C22: =COUNTIFS('DP və TP'!$B:$B,B22,'DP və TP'!$AD:$AD,"<=1") -> 3 | D22: =COUNTIFS('DP və TP'!$B:$B,B22,'DP və TP'!$X:$X,"Tam icra",'DP və TP'!$AD:$AD,"<=1") -> 1 | E22: =COUNTIFS('DP və TP'!$B:$B,B22, 'DP və TP'!$X:$X,"Qismən icra",'DP və TP'!$AD:$AD,"<=1") -> 0 | F22: =COUNTIFS('DP və TP'!$B:$B,B22, 'DP və TP'!$X:$X,"İcra müddətinə var",'DP və TP'!$AD:$AD,"<=1") -> 1 | G22: =COUNTIFS('DP və TP'!$B:$B,B22, 'DP və TP'!$X:$X,"Gecikmə",'DP və TP'!$AD:$AD,"<=1") -> 0 | H22: =COUNTIFS('DP və TP'!$B:$B,B22, 'DP və TP'!$X:$X,"İcra olunmayıb",'DP və TP'!$AD:$AD,"<=1") -> 0 | I22: =COUNTIFS('DP və TP'!$B:$B,B22, 'DP və TP'!$X:$X,"İcra olunmayıb, prioritet deyil",'DP və TP'!$AD:$AD,"<=1") -> 1 | J22: =COUNTIFS('DP və TP'!$B:$B,B22, 'DP və TP'!$K:$K,"Tapşırıqların İcrasına Nəzarət platforması üzrə", 'DP və TP'!$X:$X,"Tam icra",'DP və TP'!$AD:$AD,"<=1") -> 0 | K22: =COUNTIFS('DP və TP'!$B:$B,B22, 'DP və TP'!$K:$K,"Tapşırıqların İcrasına Nəzarət platforması üzrə", 'DP və TP'!$X:$X,"Qismən icra",'DP və TP'!$AD:$AD,"<=1") -> 0 | L22: =COUNTIFS('DP və TP'!$B:$B,B22, 'DP və TP'!$K:$K,"Tapşırıqların İcrasına Nəzarət platforması üzrə", 'DP və TP'!$X:$X,"İcra müddətinə var",'DP və TP'!$AD:$AD,"<=1") -> 0 | M22: =COUNTIFS('DP və TP'!$B:$B,B22, 'DP və TP'!$K:$K,"Tapşırıqların İcrasına Nəzarət platforması üzrə", 'DP və TP'!$X:$X,"Gecikmə",'DP və TP'!$AD:$AD,"<=1") -> 0 | N22: =COUNTIFS('DP və TP'!$B:$B,B22, 'DP və TP'!$K:$K,"Tapşırıqların İcrasına Nəzarət platforması üzrə", 'DP və TP'!$X:$X,"İcra olunmayıb",'DP və TP'!$AD:$AD,"<=1") -> 0 | O22: =COUNTIFS('DP və TP'!$B:$B,B22, 'DP və TP'!$K:$K,"Tapşırıqların İcrasına Nəzarət platforması üzrə", 'DP və TP'!$X:$X,"İcra olunmayıb, prioritet deyil",'DP və TP'!$AD:$AD,"<=1") -> 0
A23: 13 | B23: Respublikada yoxsulluğun azaldılması üzrə 2019–2022-ci illər üçün Tədbirlər Proqramı | C23: =COUNTIFS('DP və TP'!$B:$B,B23,'DP və TP'!$AD:$AD,"<=1") -> 2 | D23: =COUNTIFS('DP və TP'!$B:$B,B23,'DP və TP'!$X:$X,"Tam icra",'DP və TP'!$AD:$AD,"<=1") -> 0 | E23: =COUNTIFS('DP və TP'!$B:$B,B23, 'DP və TP'!$X:$X,"Qismən icra",'DP və TP'!$AD:$AD,"<=1") -> 0 | F23: =COUNTIFS('DP və TP'!$B:$B,B23, 'DP və TP'!$X:$X,"İcra müddətinə var",'DP və TP'!$AD:$AD,"<=1") -> 1 | G23: =COUNTIFS('DP və TP'!$B:$B,B23, 'DP və TP'!$X:$X,"Gecikmə",'DP və TP'!$AD:$AD,"<=1") -> 1 | H23: =COUNTIFS('DP və TP'!$B:$B,B23, 'DP və TP'!$X:$X,"İcra olunmayıb",'DP və TP'!$AD:$AD,"<=1") -> 0 | I23: =COUNTIFS('DP və TP'!$B:$B,B23, 'DP və TP'!$X:$X,"İcra olunmayıb, prioritet deyil",'DP və TP'!$AD:$AD,"<=1") -> 0 | J23: =COUNTIFS('DP və TP'!$B:$B,B23, 'DP və TP'!$K:$K,"Tapşırıqların İcrasına Nəzarət platforması üzrə", 'DP və TP'!$X:$X,"Tam icra",'DP və TP'!$AD:$AD,"<=1") -> 0 | K23: =COUNTIFS('DP və TP'!$B:$B,B23, 'DP və TP'!$K:$K,"Tapşırıqların İcrasına Nəzarət platforması üzrə", 'DP və TP'!$X:$X,"Qismən icra",'DP və TP'!$AD:$AD,"<=1") -> 0 | L23: =COUNTIFS('DP və TP'!$B:$B,B23, 'DP və TP'!$K:$K,"Tapşırıqların İcrasına Nəzarət platforması üzrə", 'DP və TP'!$X:$X,"İcra müddətinə var",'DP və TP'!$AD:$AD,"<=1") -> 0 | M23: =COUNTIFS('DP və TP'!$B:$B,B23, 'DP və TP'!$K:$K,"Tapşırıqların İcrasına Nəzarət platforması üzrə", 'DP və TP'!$X:$X,"Gecikmə",'DP və TP'!$AD:$AD,"<=1") -> 0 | N23: =COUNTIFS('DP və TP'!$B:$B,B23, 'DP və TP'!$K:$K,"Tapşırıqların İcrasına Nəzarət platforması üzrə", 'DP və TP'!$X:$X,"İcra olunmayıb",'DP və TP'!$AD:$AD,"<=1") -> 0 | O23: =COUNTIFS('DP və TP'!$B:$B,B23, 'DP və TP'!$K:$K,"Tapşırıqların İcrasına Nəzarət platforması üzrə", 'DP və TP'!$X:$X,"İcra olunmayıb, prioritet deyil",'DP və TP'!$AD:$AD,"<=1") -> 0 | P23: =SUM(J23:O23) -> 0
A24: 14 | B24: Respublikada ətraf mühitin mühafizəsi üzrə 2020–2025-ci illər üçün Tədbirlər Proqramı | C24: =COUNTIFS('DP və TP'!$B:$B,B24,'DP və TP'!$AD:$AD,"<=1") -> 16 | D24: =COUNTIFS('DP və TP'!$B:$B,B24,'DP və TP'!$X:$X,"Tam icra",'DP və TP'!$AD:$AD,"<=1") -> 7 | E24: =COUNTIFS('DP və TP'!$B:$B,B24, 'DP və TP'!$X:$X,"Qismən icra",'DP və TP'!$AD:$AD,"<=1") -> 3 | F24: =COUNTIFS('DP və TP'!$B:$B,B24, 'DP və TP'!$X:$X,"İcra müddətinə var",'DP və TP'!$AD:$AD,"<=1") -> 3 | G24: =COUNTIFS('DP və TP'!$B:$B,B24, 'DP və TP'!$X:$X,"Gecikmə",'DP və TP'!$AD:$AD,"<=1") -> 1 | H24: =COUNTIFS('DP və TP'!$B:$B,B24, 'DP və TP'!$X:$X,"İcra olunmayıb",'DP və TP'!$AD:$AD,"<=1") -> 0 | I24: =COUNTIFS('DP və TP'!$B:$B,B24, 'DP və TP'!$X:$X,"İcra olunmayıb, prioritet deyil",'DP və TP'!$AD:$AD,"<=1") -> 2 | J24: =COUNTIFS('DP və TP'!$B:$B,B24, 'DP və TP'!$K:$K,"Tapşırıqların İcrasına Nəzarət platforması üzrə", 'DP və TP'!$X:$X,"Tam icra",'DP və TP'!$AD:$AD,"<=1") -> 3 | K24: =COUNTIFS('DP və TP'!$B:$B,B24, 'DP və TP'!$K:$K,"Tapşırıqların İcrasına Nəzarət platforması üzrə", 'DP və TP'!$X:$X,"Qismən icra",'DP və TP'!$AD:$AD,"<=1") -> 2 | L24: =COUNTIFS('DP və TP'!$B:$B,B24, 'DP və TP'!$K:$K,"Tapşırıqların İcrasına Nəzarət platforması üzrə", 'DP və TP'!$X:$X,"İcra müddətinə var",'DP və TP'!$AD:$AD,"<=1") -> 0 | M24: =COUNTIFS('DP və TP'!$B:$B,B24, 'DP və TP'!$K:$K,"Tapşırıqların İcrasına Nəzarət platforması üzrə", 'DP və TP'!$X:$X,"Gecikmə",'DP və TP'!$AD:$AD,"<=1") -> 1 | N24: =COUNTIFS('DP və TP'!$B:$B,B24, 'DP və TP'!$K:$K,"Tapşırıqların İcrasına Nəzarət platforması üzrə", 'DP və TP'!$X:$X,"İcra olunmayıb",'DP və TP'!$AD:$AD,"<=1") -> 0 | O24: =COUNTIFS('DP və TP'!$B:$B,B24, 'DP və TP'!$K:$K,"Tapşırıqların İcrasına Nəzarət platforması üzrə", 'DP və TP'!$X:$X,"İcra olunmayıb, prioritet deyil",'DP və TP'!$AD:$AD,"<=1") -> 1 | P24: =SUM(J24:O24) -> 7
A25: 15 | B25: “Respublikada innovasiya mühitinin inkişafı üzrə 2023–2026-ci illər üçün Konsepsiyanın icrası üzrə Fəaliyyət Planı” | C25: =COUNTIFS('DP və TP'!$B:$B,B25,'DP və TP'!$AD:$AD,"<=1") -> 1 | D25: =COUNTIFS('DP və TP'!$B:$B,B25,'DP və TP'!$X:$X,"Tam icra",'DP və TP'!$AD:$AD,"<=1") -> 0 | E25: =COUNTIFS('DP və TP'!$B:$B,B25, 'DP və TP'!$X:$X,"Qismən icra",'DP və TP'!$AD:$AD,"<=1") -> 0 | F25: =COUNTIFS('DP və TP'!$B:$B,B25, 'DP və TP'!$X:$X,"İcra müddətinə var",'DP və TP'!$AD:$AD,"<=1") -> 0 | G25: =COUNTIFS('DP və TP'!$B:$B,B25, 'DP və TP'!$X:$X,"Gecikmə",'DP və TP'!$AD:$AD,"<=1") -> 0 | H25: =COUNTIFS('DP və TP'!$B:$B,B25, 'DP və TP'!$X:$X,"İcra olunmayıb",'DP və TP'!$AD:$AD,"<=1") -> 0 | I25: =COUNTIFS('DP və TP'!$B:$B,B25, 'DP və TP'!$X:$X,"İcra olunmayıb, prioritet deyil",'DP və TP'!$AD:$AD,"<=1") -> 1 | J25: =COUNTIFS('DP və TP'!$B:$B,B25, 'DP və TP'!$K:$K,"Tapşırıqların İcrasına Nəzarət platforması üzrə", 'DP və TP'!$X:$X,"Tam icra",'DP və TP'!$AD:$AD,"<=1") -> 0 | K25: =COUNTIFS('DP və TP'!$B:$B,B25, 'DP və TP'!$K:$K,"Tapşırıqların İcrasına Nəzarət platforması üzrə", 'DP və TP'!$X:$X,"Qismən icra",'DP və TP'!$AD:$AD,"<=1") -> 0 | L25: =COUNTIFS('DP və TP'!$B:$B,B25, 'DP və TP'!$K:$K,"Tapşırıqların İcrasına Nəzarət platforması üzrə", 'DP və TP'!$X:$X,"İcra müddətinə var",'DP və TP'!$AD:$AD,"<=1") -> 0 | M25: =COUNTIFS('DP və TP'!$B:$B,B25, 'DP və TP'!$K:$K,"Tapşırıqların İcrasına Nəzarət platforması üzrə", 'DP və TP'!$X:$X,"Gecikmə",'DP və TP'!$AD:$AD,"<=1") -> 0 | N25: =COUNTIFS('DP və TP'!$B:$B,B25, 'DP və TP'!$K:$K,"Tapşırıqların İcrasına Nəzarət platforması üzrə", 'DP və TP'!$X:$X,"İcra olunmayıb",'DP və TP'!$AD:$AD,"<=1") -> 0 | O25: =COUNTIFS('DP və TP'!$B:$B,B25, 'DP və TP'!$K:$K,"Tapşırıqların İcrasına Nəzarət platforması üzrə", 'DP və TP'!$X:$X,"İcra olunmayıb, prioritet deyil",'DP və TP'!$AD:$AD,"<=1") -> 1 | P25: =SUM(J25:O25) -> 1
A26: 16 | B26: Respublikada rəqəmsal xidmətlərin inkişafı üzrə 2025–2027-ci illər üçün Milli Fəaliyyət Planı | C26: =COUNTIFS('DP və TP'!$B:$B,B26,'DP və TP'!$AD:$AD,"<=1") -> 8 | D26: =COUNTIFS('DP və TP'!$B:$B,B26,'DP və TP'!$X:$X,"Tam icra",'DP və TP'!$AD:$AD,"<=1") -> 0 | E26: =COUNTIFS('DP və TP'!$B:$B,B26, 'DP və TP'!$X:$X,"Qismən icra",'DP və TP'!$AD:$AD,"<=1") -> 0 | F26: =COUNTIFS('DP və TP'!$B:$B,B26, 'DP və TP'!$X:$X,"İcra müddətinə var",'DP və TP'!$AD:$AD,"<=1") -> 2 | G26: =COUNTIFS('DP və TP'!$B:$B,B26, 'DP və TP'!$X:$X,"Gecikmə",'DP və TP'!$AD:$AD,"<=1") -> 2 | H26: =COUNTIFS('DP və TP'!$B:$B,B26, 'DP və TP'!$X:$X,"İcra olunmayıb",'DP və TP'!$AD:$AD,"<=1") -> 0 | I26: =COUNTIFS('DP və TP'!$B:$B,B26, 'DP və TP'!$X:$X,"İcra olunmayıb, prioritet deyil",'DP və TP'!$AD:$AD,"<=1") -> 4 | J26: =COUNTIFS('DP və TP'!$B:$B,B26, 'DP və TP'!$K:$K,"Tapşırıqların İcrasına Nəzarət platforması üzrə", 'DP və TP'!$X:$X,"Tam icra",'DP və TP'!$AD:$AD,"<=1") -> 0 | K26: =COUNTIFS('DP və TP'!$B:$B,B26, 'DP və TP'!$K:$K,"Tapşırıqların İcrasına Nəzarət platforması üzrə", 'DP və TP'!$X:$X,"Qismən icra",'DP və TP'!$AD:$AD,"<=1") -> 0 | L26: =COUNTIFS('DP və TP'!$B:$B,B26, 'DP və TP'!$K:$K,"Tapşırıqların İcrasına Nəzarət platforması üzrə", 'DP və TP'!$X:$X,"İcra müddətinə var",'DP və TP'!$AD:$AD,"<=1") -> 0 | M26: =COUNTIFS('DP və TP'!$B:$B,B26, 'DP və TP'!$K:$K,"Tapşırıqların İcrasına Nəzarət platforması üzrə", 'DP və TP'!$X:$X,"Gecikmə",'DP və TP'!$AD:$AD,"<=1") -> 0 | N26: =COUNTIFS('DP və TP'!$B:$B,B26, 'DP və TP'!$K:$K,"Tapşırıqların İcrasına Nəzarət platforması üzrə", 'DP və TP'!$X:$X,"İcra olunmayıb",'DP və TP'!$AD:$AD,"<=1") -> 0 | O26: =COUNTIFS('DP və TP'!$B:$B,B26, 'DP və TP'!$K:$K,"Tapşırıqların İcrasına Nəzarət platforması üzrə", 'DP və TP'!$X:$X,"İcra olunmayıb, prioritet deyil",'DP və TP'!$AD:$AD,"<=1") -> 0 | P26: =SUM(J26:O26) -> 0
A27: 17 | B27: “Respublikada könüllülük hərəkatının təşviqi üzrə 2021–2025-ci illər üçün Tədbirlər Proqramı” | C27: =COUNTIFS('DP və TP'!$B:$B,B27,'DP və TP'!$AD:$AD,"<=1") -> 10 | D27: =COUNTIFS('DP və TP'!$B:$B,B27,'DP və TP'!$X:$X,"Tam icra",'DP və TP'!$AD:$AD,"<=1") -> 2 | E27: =COUNTIFS('DP və TP'!$B:$B,B27, 'DP və TP'!$X:$X,"Qismən icra",'DP və TP'!$AD:$AD,"<=1") -> 1 | F27: =COUNTIFS('DP və TP'!$B:$B,B27, 'DP və TP'!$X:$X,"İcra müddətinə var",'DP və TP'!$AD:$AD,"<=1") -> 3 | G27: =COUNTIFS('DP və TP'!$B:$B,B27, 'DP və TP'!$X:$X,"Gecikmə",'DP və TP'!$AD:$AD,"<=1") -> 3 | H27: =COUNTIFS('DP və TP'!$B:$B,B27, 'DP və TP'!$X:$X,"İcra olunmayıb",'DP və TP'!$AD:$AD,"<=1") -> 0 | I27: =COUNTIFS('DP və TP'!$B:$B,B27, 'DP və TP'!$X:$X,"İcra olunmayıb, prioritet deyil",'DP və TP'!$AD:$AD,"<=1") -> 1 | J27: =COUNTIFS('DP və TP'!$B:$B,B27, 'DP və TP'!$K:$K,"Tapşırıqların İcrasına Nəzarət platforması üzrə", 'DP və TP'!$X:$X,"Tam icra",'DP və TP'!$AD:$AD,"<=1") -> 1 | K27: =COUNTIFS('DP və TP'!$B:$B,B27, 'DP və TP'!$K:$K,"Tapşırıqların İcrasına Nəzarət platforması üzrə", 'DP və TP'!$X:$X,"Qismən icra",'DP və TP'!$AD:$AD,"<=1") -> 0 | L27: =COUNTIFS('DP və TP'!$B:$B,B27, 'DP və TP'!$K:$K,"Tapşırıqların İcrasına Nəzarət platforması üzrə", 'DP və TP'!$X:$X,"İcra müddətinə var",'DP və TP'!$AD:$AD,"<=1") -> 3 | M27: =COUNTIFS('DP və TP'!$B:$B,B27, 'DP və TP'!$K:$K,"Tapşırıqların İcrasına Nəzarət platforması üzrə", 'DP və TP'!$X:$X,"Gecikmə",'DP və TP'!$AD:$AD,"<=1") -> 3 | N27: =COUNTIFS('DP və TP'!$B:$B,B27, 'DP və TP'!$K:$K,"Tapşırıqların İcrasına Nəzarət platforması üzrə", 'DP və TP'!$X:$X,"İcra olunmayıb",'DP və TP'!$AD:$AD,"<=1") -> 0 | O27: =COUNTIFS('DP və TP'!$B:$B,B27, 'DP və TP'!$K:$K,"Tapşırıqların İcrasına Nəzarət platforması üzrə", 'DP və TP'!$X:$X,"İcra olunmayıb, prioritet deyil",'DP və TP'!$AD:$AD,"<=1") -> 1 | P27: =SUM(J27:O27) -> 8
